<?xml version="1.0" encoding="UTF-8"?>
<!-- Generated by org.testng.reporters.JUnitReportReporter -->
<testsuite hostname="Jelica-PC" name="Login.LoginTestCases" tests="5" failures="1" timestamp="1 Oct 2019 09:38:58 GMT" time="18.754" errors="0">
  <testcase name="VerifyElementsOnThePage" time="3.051" classname="Login.LoginTestCases"/>
  <testcase name="LogInWithWrongEmail" time="3.560" classname="Login.LoginTestCases"/>
  <testcase name="LogInWithoutEmail" time="4.968" classname="Login.LoginTestCases"/>
  <testcase name="SuccessfullyLogIn" time="3.555" classname="Login.LoginTestCases">
    <failure type="java.lang.AssertionError" message="expected:&lt;https://www.phptravels.net/account/&gt; but was:&lt;https://www.phptravels.net/login&gt;">
      <![CDATA[java.lang.AssertionError: expected:<https://www.phptravels.net/account/> but was:<https://www.phptravels.net/login>
	at org.testng.AssertJUnit.assertEquals(AssertJUnit.java:101)
	at org.testng.AssertJUnit.assertEquals(AssertJUnit.java:108)
	at Login.LoginTestCases.SuccessfullyLogIn(LoginTestCases.java:73)
	at sun.reflect.NativeMethodAccessorImpl.invoke0(Native Method)
	at sun.reflect.NativeMethodAccessorImpl.invoke(Unknown Source)
	at sun.reflect.DelegatingMethodAccessorImpl.invoke(Unknown Source)
	at java.lang.reflect.Method.invoke(Unknown Source)
	at org.testng.internal.MethodInvocationHelper.invokeMethod(MethodInvocationHelper.java:86)
	at org.testng.internal.Invoker.invokeMethod(Invoker.java:646)
	at org.testng.internal.Invoker.invokeTestMethod(Invoker.java:823)
	at org.testng.internal.Invoker.invokeTestMethods(Invoker.java:1131)
	at org.testng.internal.TestMethodWorker.invokeTestMethods(TestMethodWorker.java:129)
	at org.testng.internal.TestMethodWorker.run(TestMethodWorker.java:112)
	at org.testng.TestRunner.privateRun(TestRunner.java:778)
	at org.testng.TestRunner.run(TestRunner.java:632)
	at org.testng.SuiteRunner.runTest(SuiteRunner.java:366)
	at org.testng.SuiteRunner.runSequentially(SuiteRunner.java:361)
	at org.testng.SuiteRunner.privateRun(SuiteRunner.java:319)
	at org.testng.SuiteRunner.run(SuiteRunner.java:268)
	at org.testng.SuiteRunnerWorker.runSuite(SuiteRunnerWorker.java:52)
	at org.testng.SuiteRunnerWorker.run(SuiteRunnerWorker.java:86)
	at org.testng.TestNG.runSuitesSequentially(TestNG.java:1225)
	at org.testng.TestNG.runSuitesLocally(TestNG.java:1150)
	at org.testng.TestNG.runSuites(TestNG.java:1075)
	at org.testng.TestNG.run(TestNG.java:1047)
	at org.testng.remote.AbstractRemoteTestNG.run(AbstractRemoteTestNG.java:126)
	at org.testng.remote.RemoteTestNG.initAndRun(RemoteTestNG.java:137)
	at org.testng.remote.RemoteTestNG.main(RemoteTestNG.java:58)
]]>
    </failure>
  </testcase> <!-- SuccessfullyLogIn -->
  <testcase name="LogInWithoutPassword" time="3.620" classname="Login.LoginTestCases"/>
</testsuite> <!-- Login.LoginTestCases -->
